Workbook
Name Slicer_AREA: #N/A
Name Slicer_Delivery1: #N/A
Name Slicer_GATE_IN: #N/A
Name Slicer_Name_ship_to_party: #N/A
Name Slicer_TRUCK_TYPE: #N/A
Name Slicer_Vendor: #N/A

Sheet Aug
B1: DAY | C1: =TODAY() -> 45977
A5: Tanggal | B5: Delivery | C5: Vendor | D5: FO Number | E5: Name ship-to party | F5: Net Weight | G5: Total Weight | H5: Plat NO | I5: Telp
A6: 15/08/2025 | B6: 3331542053 | C6: YUSHAR | D6: 24140085 | E6: PT. KEMASAN INDAH SEJAHTERA | F6: BANTEN | G6: 23317 | H6: B 9253 KYZ | K6: 3331545243 | L6: =VLOOKUP(K6,B:C,2,FALSE) -> HOLD
A7: 15/08/2025 | B7: 3331542063 | C7: YUSHAR | D7: 24140086 | E7: PT. KEMASAN INDAH SEJAHTERA | F7: BANTEN | G7: 23431 | H7: B 9918 KYT | K7: 3331546299 | L7: =VLOOKUP(K7,B:C,2,FALSE) -> BIMARUNA trailer
A8: 15/08/2025 | B8: 3331542354 | C8: YUSHAR | D8: 24140088 | E8: ASADA MITRA PACKINDO, PT | F8: BALARAJA - TANGERANG | G8: 24200 | H8: B 9946 KIT | K8: 3331546331 | L8: =VLOOKUP(K8,B:C,2,FALSE) -> ALIEF bongkar senin
A9: 15/08/2025 | B9: 3331542112 | C9: YUSHAR | D9: 24140089 | E9: PT. KEMASAN INDAH SEJAHTERA | F9: BANTEN | G9: 24731 | H9: B 9398 KYZ | K9: 3331546342 | L9: =VLOOKUP(K9,B:C,2,FALSE) -> #N/A
A10: 15/08/2025 | B10: 3331543113 | C10: YUSHAR | D10: 24140092 | E10: ASADA MITRA PACKINDO, PT | F10: BALARAJA - TANGERANG | G10: 16615 | H10: B 9657 KYZ | K10: 3331547864 | L10: =VLOOKUP(K10,B:C,2,FALSE) -> SIBA
A11: 15/08/2025 | B11: 3331542464 | C11: YUSHAR | D11: 24140090 | E11: PT. KEMASAN INDAH SEJAHTERA | F11: BANTEN | G11: 24731 | H11: B 9026 PFA | K11: 3331547878 | L11: =VLOOKUP(K11,B:C,2,FALSE) -> 0
A12: 18/08/2025 | B12: 3331541998 | C12: YUSHAR | D12: 24140093 | E12: PT.ALKINDO NARATAMA Tbk | F12: KAB. BANDUNG BARAT,JAWA BARAT | G12: 24000 | H12: B 9681 PDC | K12: 3331547881 | L12: =VLOOKUP(K12,B:C,2,FALSE) -> SIBA
A13: 18/08/2025 | B13: 3331542352 | C13: SILOG | D13: 24140094 | E13: PT MULIAPRIMA PACKINDO | F13: BEKASI | G13: 25600 | H13: K 8465 OD | K13: 3331547892 | L13: =VLOOKUP(K13,B:C,2,FALSE) -> ALIEF
A14: 18/08/2025 | B14: 3331544015 | C14: SILOG | D14: 24140095 | E14: PT MULIAPRIMA PACKINDO | F14: BEKASI | G14: 24900 | H14: W 9818 UK | K14: 3331547893 | L14: =VLOOKUP(K14,B:C,2,FALSE) -> PT MALABA
A15: 18/08/2025 | B15: 3331543511 | C15: YUSHAR | D15: 24140096 | E15: ASADA MITRA PACKINDO, PT | F15: BALARAJA - TANGERANG | G15: 25100 | H15: B 9877 UDG | K15: 3331547898 | L15: =VLOOKUP(K15,B:C,2,FALSE) -> 0
A16: 18/08/2025 | B16: 3331544021 | C16: YUSHAR | D16: 24140097 | E16: ASADA MITRA PACKINDO, PT | F16: BALARAJA - TANGERANG | G16: 25000 | H16: B 9345 KYV | K16: 3331547900 | L16: =VLOOKUP(K16,B:C,2,FALSE) -> ALIEF
A17: 18/08/2025 | B17: 3331543465 | C17: ALIEF | D17: 24140098 | E17: PT. KEMASAN INDAH SEJAHTERA | F17: BANTEN | G17: 25372 | H17: B 9996 TIS | K17: 3331547902 | L17: =VLOOKUP(K17,B:C,2,FALSE) -> 0
... A21: 18.08.2025 | B21: 3331544029 | C21: YUSHAR | D21: 24140101 | E21: PT MULTI ARTHA ABADI | F21: TANGERANG | G21: 25162 | H21: B 9946 KIT | K21: 3331548394 | L21: =VLOOKUP(K21,B:C,2,FALSE) -> #N/A
A22: 19/08/2025 | B22: 3331544443 | C22: ALIEF | D22: 24140104 | E22: PT.ALKINDO NARATAMA Tbk | F22: BANDUNG | G22: 22500 | K22: 3331548636 | L22: =VLOOKUP(K22,B:C,2,FALSE) -> #N/A
A23: 19/08/2025 | B23: 3331544442 | C23: SILOG | D23: 24140103 | E23: PT MULIAPRIMA PACKINDO | F23: BEKASI | G23: 26050 | H23: S 9164 UH | K23: 3331548644 | L23: =VLOOKUP(K23,B:C,2,FALSE) -> #N/A
A24: 19/08/2025 | B24: 3331544432 | C24: ALIEF | D24: 24140111 | E24: PT. SETIAJAYA KEMASINDO MADYA | F24: TANGERANG | G24: 25850 | K24: 3331548645 | L24: =VLOOKUP(K24,B:C,2,FALSE) -> #N/A
A25: 19/08/2025 | B25: 3331544436 | C25: SILOG | D25: 24140112 | E25: PT. SETIAJAYA KEMASINDO MADYA | F25: TANGERANG | G25: 24850 | K25: 3331548760 | L25: =VLOOKUP(K25,B:C,2,FALSE) -> #N/A
A26: 19/08/2025 | B26: 3331544144 | C26: YUSHAR | D26: 24140107 | E26: MULTI ARTHA ABADI, PT | F26: TANGERANG | G26: 25950 | H26: KB 8001 HC | K26: 3331548761 | L26: =VLOOKUP(K26,B:C,2,FALSE) -> #N/A
A27: 19/08/2025 | B27: 3331544416 | C27: SILOG | D27: 24140113 | E27: PT MULTI ARTHA ABADI | F27: TANGERANG | G27: 20150
A28: 19/08/2025 | B28: 3331544154 | C28: YUSHAR | D28: 24140108 | E28: PT. ADINA MULTI WAHANA | F28: TANGERANG | G28: 25400
A29: 19/08/2025 | B29: 3331543467 | C29: YUSHAR | D29: 24140109 | E29: PT. KEMASAN INDAH SEJAHTERA | F29: TANGERANG | G29: 23758
A30: 19/08/2025 | B30: 3331544483 | C30: SILOG | D30: 24140106 | E30: PT. TRISTAR MAKMUR KARTONINDO, GD | F30: BEKASI | G30: 21100
A31: 19/08/2025 | B31: 3331544464 | C31: ETI | D31: 24140105 | E31: ASADA MITRA PACKINDO, PT | F31: KARAWACI - TANGERANG | G31: 21600
A32: 19/08/2025 | B32: 3331544444 | C32: ALIEF | D32: 24140110 | E32: ASADA MITRA PACKINDO, PT | F32: KARAWACI - TANGERANG | G32: 19372 | H32: B 9996 TIS
A33: 45889 | B33: 3331544464 | C33: Yushar | D33: 24140105 | E33: ASADA MITRA PACKINDO, PT | F33: BALARAJA | G33: 21708 | H33: B 9841 FYV | I33: 85607439827
A34: 45889 | B34: 3331544029 | C34: alief | D34: 24140102 | E34: PT. ADINA MULTI WAHANA | F34: TANGERANG | G34: 25125 | H34: B 9697 WW | I34: =IFERROR(VLOOKUP(B33, '[1]Status MLS'!K:K,8, FALSE), "")
A35: 45889 | B35: 3331544154 | C35: Transindo | D35: 24140108 | E35: PT. ADINA MULTI WAHANA | F35: TANGERANG | G35: 25527 | H35: B 9947 NU
A36: 45889 | B36: 3331543467 | C36: CGL | D36: 24140109 | E36: PT. KEMASAN INDAH SEJAHTERA | F36: CIKUPA | G36: 23900.548 | H36: B 9086 PYX
A37: 45889 | B37: 3331544432 | C37: silog | D37: 24140111 | E37: PT. SETIAJAYA KEMASINDO MADYA | F37: TANGERANG | G37: 25979.25 | H37: S 9843 UE | I37: 838962631
A38: 45889 | B38: 3331544436 | C38: silog | D38: 24140112 | E38: PT. SETIAJAYA KEMASINDO MADYA | F38: TANGERANG | G38: 24974.25 | H38: S 8875 UE | I38: 81345383250
A39: 45889 | B39: 3331544443 | C39: eti | D39: 24140104 | E39: PT.ALKINDO NARATAMA Tbk | F39: BANDUNG | G39: 22612.5 | H39: B 9755 UYZ
A40: 45889 | B40: 3331544776 | C40: cgl | D40: 24140115 | E40: PT. KEMASAN INDAH SEJAHTERA | F40: CIKUPA | G40: 22527.358 | H40: B 9083 PYX | I40: 89527267983
A41: 45889 | B41: 3331544783 | C41: alief | D41: 24140117 | E41: PT MULIAPRIMA PACKINDO | F41: CIKARANG | G41: 26582.25 | H41: B 9165 TIW
A42: 45889 | B42: 3331544483 | C42: silog | D42: 24140106 | E42: PT. TRISTAR MAKMUR KARTONINDO, GD | F42: BEKASI | G42: 20958.27
A43: 45889 | B43: 3331544937 | C43: alief | D43: 24140118 | E43: PT. GLOBAL PAPYRUS SEMESTA | F43: KAB. BANDUNG | G43: 23969.25 | H43: B 9166 TIW
A44: 45890 | B44: 3331545151 | C44: silog | D44: 24140119 | E44: MULTI ARTHA ABADI, PT | F44: TANGERANG | G44: 25750 | H44: S 8818 UE | I44: 8776217011
A45: 45890 | B45: 3331545152 | C45: silog | D45: 24140120 | E45: MULTI ARTHA ABADI, PT | F45: TANGERANG | G45: 25875 | H45: S 8817 UE | I45: TIDAK ADA
A46: 45890 | B46: 3331544804 | C46: silog | D46: 24140123 | E46: PT MULIAPRIMA PACKINDO | F46: BEKASI | G46: 25728 | H46: S 8425 OD | I46: TIDAK ADA
...

Sheet SEP  (2)
I1: *PLAN | J1: =J2+J3 -> 21 | K1: *AKTUAL | L1: =SUM(L2:L7) -> 19
A2: DATE | B2: =TODAY() -> 45977 | E2: AREA | F2: QTY TRUCK | G2: TONASE (MT) | I2: TRAILER | J2: =SUMIF(H61:I1036, "TRAILER", I61:J1035) -> 11 | K2: SILOG | L2: =COUNTIF(C60:C1018,"SILOG") -> 7
A3: TRUCK PLAN | B3: =SUM(I61:I114) -> 21 | E3: JABODETABEK | F3: =COUNTIF(F61:F1037, "JABODETABEK") -> 10 | G3: =SUMIF(F61:F1037, "JABODETABEK", G38:G1037) -> 345166.65 | I3: TRONTON | J3: =SUMIF(H61:I1037, "TRONTON", I61:J1036) -> 10 | K3: SIBA | L3: =COUNTIF(C61:C1019,"SIBA") -> 1
A4: TRUCK AVAILABLE | B4: =SUM(J61:J165) -> 19 | C4: *Sudah terkonfirmasi | E4: JAWA TENGAH | F4: =COUNTIF($F$61:F1038, "JAWA TENGAH") -> 9 | G4: =SUMIF(F61:F1038, "JAWA TENGAH", G38:G1037) -> 246666.17 | K4: YUSHAR | L4: =COUNTIF(C61:C1019,"YUSHAR") -> 1
A5: MASUK | B5: {=SUMPRODUCT(--(ISNUMBER(K61:K1014)))} -> 1 | E5: JAWA TIMUR | F5: =COUNTIF($F$61:F1039, "JAWA TIMUR") -> 2 | G5: =SUMIF(F61:F1039, "JAWA TIMUR", G39:G1038) -> 85371.335 | K5: BRJ | L5: =COUNTIF(C61:C1019,"BRJ") -> 4
A6: BELUM MASUK | B6: =COUNTIF(K60:K1014,"BELUM MASUK") -> 20 | E6: TOTAL PLAN | F6: =SUM(F3:F5) -> 21 | G6: =SUM(G3:G5) -> 677204.16 | K6: ALIEF | L6: =COUNTIF(C62:C1020,"ALIEF") -> 3
A7: KEKURANGAN TRUCK | B7: =B3-B4 -> 2 | C7: *2 TRAILER | K7: ELANG | L7: =COUNTIF(C63:C1021,"ELANG") -> 3
A9: Tanggal | B9: Delivery | C9: Vendor | D9: SN | E9: Name ship-to party | F9: AREA | G9: TOTAL WEIGHT | H9: TRUCK TYPE | I9: QTY KEBUTUHAN | J9: KETERSEDIAAN | K9: GATE IN | L9: GATE OUT
A10: 01.09.2025 | B10: 3331548306 | C10: ETI | D10: 24140272 | E10: PT. KATI KARTIKA MURNI CIKARANG | F10: JABODETABEK | G10: 25 | H10: TRONTON | I10: 1 | J10: 1
A11: 01.09.2025 | B11: 3331548307 | C11: CGL | D11: 24140273 | E11: PT. KATI KARTIKA MURNI CIKARANG | F11: JABODETABEK | G11: 25 | H11: TRONTON | I11: 1 | J11: 1
A12: 01.09.2025 | B12: 3331547906 | C12: ALIEF | D12: 24140274 | E12: PT. DAYACIPTA KEMASINDO (GD) KARAWANG | F12: JABODETABEK | G12: 25 | H12: TRONTON | I12: 1 | J12: 1
A13: 01.09.2025 | B13: 3331548297 | C13: ALIEF | D13: 24140275 | E13: PT. DAYACIPTA KEMASINDO (GD) KARAWANG | F13: JABODETABEK | G13: 25 | H13: TRONTON | I13: 1 | J13: 1
A14: 02.09.2025 | B14: 3331548390 | C14: ALIEF | D14: 24140284 | E14: PT. DAYACIPTA KEMASINDO (GD) | F14: JABODETABEK | G14: 25 | H14: TRONTON | I14: 1 | J14: 1
A15: 02.09.2025 | B15: 3331548324 | C15: ETI | D15: 24140281 | E15: PT. APP PURINUSA EKAPERSADA SUBANG | F15: JABODETABEK | G15: 25 | H15: TRONTON | I15: 1 | J15: 1
A16: 01.09.2025 | B16: 3331548346 | E16: PT. APP PURINUSA EKAPERSADA | F16: JABODETABEK | G16: 25 | H16: TRONTON | I16: 1 | J16: 1
A17: 01.09.2025 | B17: 3331548331 | C17: CGL | D17: 24140277 | E17: PT. APP PURINUSA EKAPERSADA SUBANG | F17: JABODETABEK | G17: 25 | H17: TRONTON | I17: 1 | J17: 1
A18: 01.09.2025 | B18: 3331548348 | C18: ALIEF | D18: 24140279 | E18: PT. APP PURINUSA EKAPERSADA BANDUNG | F18: JABODETABEK | G18: 25 | H18: TRONTON | I18: 1 | J18: 1
A19: 01.09.2025 | B19: 3331548351 | C19: SILOG | D19: 24140280 | E19: DAYACIPTA KEMASINDO, PT (GD) Cibitung | F19: JABODETABEK | G19: 25 | H19: TRONTON | I19: 1 | J19: 1
A20: 02.09.2025 | B20: 3331548298 | C20: SILOG | D20: 24140282 | E20: PT DAYACIPTA KEMASINDO TANGERANG | F20: JABODETABEK | G20: 25 | H20: TRONTON | I20: 1 | J20: 1
A21: 01.09.2025 | B21: 3331547489 | C21: ALIEF | D21: 24140283 | E21: MULTI ARTHA ABADI, PT | F21: JABODETABEK | G21: 25 | H21: TRONTON | I21: 1 | J21: 1
A22: 01.09.2025 | B22: 3331548380 | E22: MULTI ARTHA ABADI, PT | F22: JABODETABEK | G22: 25 | H22: TRONTON | I22: 1 | J22: 1
A23: 02.09.2025 | B23: 3331548645 | C23: ALIEF | D23: 24140302 | E23: PT.SANTOSO JAWI (GD) SIDOARJO | F23: JAWA TIMUR | G23: 26525 | H23: TRONTON | I23: 1 | J23: 1
A24: 02.09.2025 | B24: 3331548670 | C24: ALIEF | D24: 24140304 | E24: PT. APP PURINUSA EKAPERSADA BANDUNG | F24: JABODETABEK | G24: 13000 | H24: TRONTON | I24: 1 | J24: 1
A25: 02.09.2025 | B25: 3331548667 | C25: ALIEF | E25: PT. APP PURINUSA EKAPERSADA | F25: JABODETABEK | G25: 11348 | H25: TRONTON | I25: 1 | J25: 1
A26: 02.09.2025 | B26: 3331548673 | C26: ALIEF | D26: 24140290 | E26: PT. KATI KARTIKA MURNI CIKARANG | F26: JABODETABEK | G26: 24763 | H26: TRONTON | I26: 1 | J26: 1
A27: 02.09.2025 | B27: 3331548675 | C27: ALIEF | D27: 24140291 | E27: PT. APP PURINUSA EKAPERSADA | F27: JABODETABEK | G27: 22060 | H27: TRONTON | I27: 1 | J27: 1
A28: 01.09.2025 | B28: 3331548333 | C28: ALIEF | D28: 24140295 | E28: PT. APP PURINUSA EKAPERSADA | F28: JABODETABEK | G28: 22060 | H28: TRONTON | I28: 1 | J28: 1
A29: 02.09.2025 | B29: 3331548732 | C29: BRJ | D29: 24140296 | E29: PT. APP PURINUSA EKAPERSADA DEMAK | F29: JAWA TENGAH | G29: 33872 | H29: TRAILER | I29: 1 | J29: 1
A30: 02.09.2025 | B30: 3331548736 | C30: BRJ | D30: 24140297 | E30: PT. APP PURINUSA EKAPERSADA DEMAK | F30: JAWA TENGAH | G30: 44529 | H30: TRAILER | I30: 1 | J30: 1
A31: 02.09.2025 | B31: 3331548741 | C31: BRJ | D31: 24140298 | E31: PT. APP PURINUSA EKAPERSADA DEMAK | F31: JAWA TENGAH | G31: 45726 | H31: TRAILER | I31: 1 | J31: 1
A32: 02.09.2025 | B32: 3331548746 | C32: BRJ | D32: 24140299 | E32: PT. APP PURINUSA EKAPERSADA SEMARANG | F32: JAWA TENGAH | G32: 37035 | H32: TRAILER | I32: 1 | J32: 1
A33: 02.09.2025 | B33: 3331548749 | C33: BRJ | D33: 24140300 | E33: PT. APP PURINUSA EKAPERSADA SEMARANG | F33: JAWA TENGAH | G33: 33812 | H33: TRAILER | I33: 1 | J33: 1
A34: 02.09.2025 | B34: 3331548756 | C34: SIBA | D34: 24140301 | E34: PT. APP PURINUSA EKAPERSADA SEMARANG | F34: JAWA TENGAH | G34: 34290 | H34: TRAILER | I34: 1 | J34: 1
A35: 02.09.2025 | B35: 3331548760 | C35: ALIEF | D35: 24140303 | E35: PT. KEMASAN INDAH SEJAHTERA | F35: JABODETABEK | G35: 13963 | H35: TRONTON | I35: 1 | J35: 1
A36: 02.09.2025 | B36: 3331548761 | E36: PT. KEMASAN INDAH SEJAHTERA | F36: JABODETABEK | G36: 10480 | H36: TRONTON | I36: 1 | J36: 1
A37: 02.09.2025 | B37: 3331548736 | C37: BRJ | D37: 24140297 | E37: PT. APP PURINUSA EKAPERSADA DEMAK | F37: JAWA TENGAH | G37: 44529 | H37: TRAILER | I37: 1 | J37: 1 | K37: 0.17986111 | L37: 0.44444444
A38: 02.09.2025 | B38: 3331548749 | C38: ETI | D38: 24140300 | E38: PT. APP PURINUSA EKAPERSADA BAWEN | F38: JAWA TENGAH | G38: 35775.372 | H38: TRAILER | I38: 1 | J38: 1 | K38: =IFERROR(VLOOKUP(B38,'IN OUT'!F:G,2,FALSE), "BELUM MASUK") -> BELUM MASUK | L38: 0.090277778
A39: 02.09.2025 | B39: 3331548756 | C39: SIBA SURYA | D39: 24140301 | E39: PT. APP PURINUSA EKAPERSADA | F39: JAWA TENGAH | G39: 34495.741 | H39: TRAILER | I39: 1 | J39: 1 | K39: =IFERROR(VLOOKUP(B39,'IN OUT'!F:G,2,FALSE), "BELUM MASUK") -> BELUM MASUK | L39: -
A40: 03.09.2025 | B40: 3331548394 | C40: ALIEF | D40: 24140305 | E40: PT. HEXA PRIMA PERSADA TGR | F40: JABODETABEK | G40: 26626.47 | H40: TRONTON | I40: 1 | J40: 1 | K40: =IFERROR(VLOOKUP(B40,'IN OUT'!F:G,2,FALSE), "BELUM MASUK") -> BELUM MASUK | L40: 0.84027778
A41: 03.09.2025 | B41: 3331548958 | C41: BRJ | D41: 24140306 | E41: PT. APP PURINUSA EKAPERSADA DEMAK | F41: JAWA TENGAH | G41: 42969.278 | H41: TRAILER | I41: 1 | J41: 1 | K41: =IFERROR(VLOOKUP(B41,'IN OUT'!F:G,2,FALSE), "BELUM MASUK") -> BELUM MASUK | L41: -
...

Sheet LONG WEEKEND
A2: DATE | B2: =TODAY() -> 45977 | E2: TRUCK TYPE | H2: PLAN AREA | I2: QTY TRUCK | J2: TONASE (MT)
A3: TRUCK PLAN | B3: =SUM(I62:I108) -> 44 | E3: TRAILER | F3: =SUMIF(H62:H108, "TRAILER", I62:I108) -> 18 | H3: JABODETABEK | I3: =COUNTIF(F62:F108, "JABODETABEK") -> 26 | J3: =SUMIF(F62:F108, "JABODETABEK", G62:G108) -> 604530.6
A4: TRUCK AVAILABLE | B4: =SUM(J62:J108) -> 44 | E4: TRONTON | F4: =SUMIF(H62:H108, "TRONTON", J62:J108) -> 26 | H4: JAWA TENGAH | I4: =COUNTIF($F$62:F108, "JAWA TENGAH") -> 15 | J4: =SUMIF(F62:F108, "JAWA TENGAH", G62:G108) -> 513186.01
A5: MASUK | B5: =COUNTIF(K62:K108,"MASUK") -> 44 | H5: JAWA TIMUR | I5: =COUNTIF($F$62:F108, "JAWA TIMUR") -> 3 | J5: =SUMIF(F62:F108, "JAWA TIMUR", G62:G108) -> 132788.64
A6: BELUM MASUK | B6: =COUNTIF(K62:K108,"BELUM MASUK") -> 0 | H6: TOTAL PLAN | I6: =SUM(I3:I5) -> 44 | J6: =SUM(J3:J5) -> 1250505.2 | K6: *CARRY OVER 0
A7: KURANG TRUCK | B7: =B3-B4 -> 0 | C7: *TRAILER
A10: Tanggal | B10: Delivery | C10: Vendor | D10: SN | E10: Name ship-to party | F10: AREA | G10: TOTAL WEIGHT | H10: TRUCK TYPE | I10: QTY KEBUTUHAN | J10: KETERSEDIAAN | K10: GATE IN | L10: GATE OUT
A11: 01.09.2025 | B11: 3331548306 | C11: ETI | D11: 24140272 | E11: PT. KATI KARTIKA MURNI CIKARANG | F11: JABODETABEK | G11: 25 | H11: TRONTON | I11: 1 | J11: 1
A12: 01.09.2025 | B12: 3331548307 | C12: CGL | D12: 24140273 | E12: PT. KATI KARTIKA MURNI CIKARANG | F12: JABODETABEK | G12: 25 | H12: TRONTON | I12: 1 | J12: 1
A13: 01.09.2025 | B13: 3331547906 | C13: ALIEF | D13: 24140274 | E13: PT. DAYACIPTA KEMASINDO (GD) KARAWANG | F13: JABODETABEK | G13: 25 | H13: TRONTON | I13: 1 | J13: 1
A14: 01.09.2025 | B14: 3331548297 | C14: ALIEF | D14: 24140275 | E14: PT. DAYACIPTA KEMASINDO (GD) KARAWANG | F14: JABODETABEK | G14: 25 | H14: TRONTON | I14: 1 | J14: 1
A15: 02.09.2025 | B15: 3331548390 | C15: ALIEF | D15: 24140284 | E15: PT. DAYACIPTA KEMASINDO (GD) | F15: JABODETABEK | G15: 25 | H15: TRONTON | I15: 1 | J15: 1
A16: 02.09.2025 | B16: 3331548324 | C16: ETI | D16: 24140281 | E16: PT. APP PURINUSA EKAPERSADA SUBANG | F16: JABODETABEK | G16: 25 | H16: TRONTON | I16: 1 | J16: 1
A17: 01.09.2025 | B17: 3331548346 | E17: PT. APP PURINUSA EKAPERSADA | F17: JABODETABEK | G17: 25 | H17: TRONTON | I17: 1 | J17: 1
A18: 01.09.2025 | B18: 3331548331 | C18: CGL | D18: 24140277 | E18: PT. APP PURINUSA EKAPERSADA SUBANG | F18: JABODETABEK | G18: 25 | H18: TRONTON | I18: 1 | J18: 1
A19: 01.09.2025 | B19: 3331548348 | C19: ALIEF | D19: 24140279 | E19: PT. APP PURINUSA EKAPERSADA BANDUNG | F19: JABODETABEK | G19: 25 | H19: TRONTON | I19: 1 | J19: 1
A20: 01.09.2025 | B20: 3331548351 | C20: SILOG | D20: 24140280 | E20: DAYACIPTA KEMASINDO, PT (GD) Cibitung | F20: JABODETABEK | G20: 25 | H20: TRONTON | I20: 1 | J20: 1
A21: 02.09.2025 | B21: 3331548298 | C21: SILOG | D21: 24140282 | E21: PT DAYACIPTA KEMASINDO TANGERANG | F21: JABODETABEK | G21: 25 | H21: TRONTON | I21: 1 | J21: 1
A22: 01.09.2025 | B22: 3331547489 | C22: ALIEF | D22: 24140283 | E22: MULTI ARTHA ABADI, PT | F22: JABODETABEK | G22: 25 | H22: TRONTON | I22: 1 | J22: 1
A23: 01.09.2025 | B23: 3331548380 | E23: MULTI ARTHA ABADI, PT | F23: JABODETABEK | G23: 25 | H23: TRONTON | I23: 1 | J23: 1
A24: 02.09.2025 | B24: 3331548645 | C24: ALIEF | D24: 24140302 | E24: PT.SANTOSO JAWI (GD) SIDOARJO | F24: JAWA TIMUR | G24: 26525 | H24: TRONTON | I24: 1 | J24: 1
A25: 02.09.2025 | B25: 3331548670 | C25: ALIEF | D25: 24140304 | E25: PT. APP PURINUSA EKAPERSADA BANDUNG | F25: JABODETABEK | G25: 13000 | H25: TRONTON | I25: 1 | J25: 1
A26: 02.09.2025 | B26: 3331548667 | C26: ALIEF | E26: PT. APP PURINUSA EKAPERSADA | F26: JABODETABEK | G26: 11348 | H26: TRONTON | I26: 1 | J26: 1
A27: 02.09.2025 | B27: 3331548673 | C27: ALIEF | D27: 24140290 | E27: PT. KATI KARTIKA MURNI CIKARANG | F27: JABODETABEK | G27: 24763 | H27: TRONTON | I27: 1 | J27: 1
A28: 02.09.2025 | B28: 3331548675 | C28: ALIEF | D28: 24140291 | E28: PT. APP PURINUSA EKAPERSADA | F28: JABODETABEK | G28: 22060 | H28: TRONTON | I28: 1 | J28: 1
A29: 01.09.2025 | B29: 3331548333 | C29: ALIEF | D29: 24140295 | E29: PT. APP PURINUSA EKAPERSADA | F29: JABODETABEK | G29: 22060 | H29: TRONTON | I29: 1 | J29: 1
A30: 02.09.2025 | B30: 3331548732 | C30: BRJ | D30: 24140296 | E30: PT. APP PURINUSA EKAPERSADA DEMAK | F30: JAWA TENGAH | G30: 33872 | H30: TRAILER | I30: 1 | J30: 1
A31: 02.09.2025 | B31: 3331548736 | C31: BRJ | D31: 24140297 | E31: PT. APP PURINUSA EKAPERSADA DEMAK | F31: JAWA TENGAH | G31: 44529 | H31: TRAILER | I31: 1 | J31: 1
A32: 02.09.2025 | B32: 3331548741 | C32: BRJ | D32: 24140298 | E32: PT. APP PURINUSA EKAPERSADA DEMAK | F32: JAWA TENGAH | G32: 45726 | H32: TRAILER | I32: 1 | J32: 1
A33: 02.09.2025 | B33: 3331548746 | C33: BRJ | D33: 24140299 | E33: PT. APP PURINUSA EKAPERSADA SEMARANG | F33: JAWA TENGAH | G33: 37035 | H33: TRAILER | I33: 1 | J33: 1
A34: 02.09.2025 | B34: 3331548749 | C34: BRJ | D34: 24140300 | E34: PT. APP PURINUSA EKAPERSADA SEMARANG | F34: JAWA TENGAH | G34: 33812 | H34: TRAILER | I34: 1 | J34: 1
A35: 02.09.2025 | B35: 3331548756 | C35: SIBA | D35: 24140301 | E35: PT. APP PURINUSA EKAPERSADA SEMARANG | F35: JAWA TENGAH | G35: 34290 | H35: TRAILER | I35: 1 | J35: 1
A36: 02.09.2025 | B36: 3331548760 | C36: ALIEF | D36: 24140303 | E36: PT. KEMASAN INDAH SEJAHTERA | F36: JABODETABEK | G36: 13963 | H36: TRONTON | I36: 1 | J36: 1
A37: 02.09.2025 | B37: 3331548761 | E37: PT. KEMASAN INDAH SEJAHTERA | F37: JABODETABEK | G37: 10480 | H37: TRONTON | I37: 1 | J37: 1
A38: 02.09.2025 | B38: 3331548736 | C38: BRJ | D38: 24140297 | E38: PT. APP PURINUSA EKAPERSADA DEMAK | F38: JAWA TENGAH | G38: 44529 | H38: TRAILER | I38: 1 | J38: 1 | K38: 0.17986111 | L38: 0.44444444
A39: 02.09.2025 | B39: 3331548749 | C39: ETI | D39: 24140300 | E39: PT. APP PURINUSA EKAPERSADA BAWEN | F39: JAWA TENGAH | G39: 35775.372 | H39: TRAILER | I39: 1 | J39: 1 | K39: =IFERROR(VLOOKUP(B39,'IN OUT'!F:G,2,FALSE), "BELUM MASUK") -> BELUM MASUK | L39: 0.090277778
A40: 02.09.2025 | B40: 3331548756 | C40: SIBA SURYA | D40: 24140301 | E40: PT. APP PURINUSA EKAPERSADA | F40: JAWA TENGAH | G40: 34495.741 | H40: TRAILER | I40: 1 | J40: 1 | K40: =IFERROR(VLOOKUP(B40,'IN OUT'!F:G,2,FALSE), "BELUM MASUK") -> BELUM MASUK | L40: -
A41: 03.09.2025 | B41: 3331548394 | C41: ALIEF | D41: 24140305 | E41: PT. HEXA PRIMA PERSADA TGR | F41: JABODETABEK | G41: 26626.47 | H41: TRONTON | I41: 1 | J41: 1 | K41: =IFERROR(VLOOKUP(B41,'IN OUT'!F:G,2,FALSE), "BELUM MASUK") -> BELUM MASUK | L41: 0.84027778
A42: 03.09.2025 | B42: 3331548958 | C42: BRJ | D42: 24140306 | E42: PT. APP PURINUSA EKAPERSADA DEMAK | F42: JAWA TENGAH | G42: 42969.278 | H42: TRAILER | I42: 1 | J42: 1 | K42: =IFERROR(VLOOKUP(B42,'IN OUT'!F:G,2,FALSE), "BELUM MASUK") -> BELUM MASUK | L42: -
A43: 03.09.2025 | B43: 3331548967 | C43: SIBA SURYA | D43: 24140307 | E43: PT. APP PURINUSA EKAPERSADA DEMAK | F43: JAWA TENGAH | G43: 43071.89 | H43: TRAILER | I43: 1 | J43: 1 | K43: 0.71081019 | L43: 0.0625
...

Sheet 11.09.25
A1: TIME | B1: =NOW() -> 45977.421 | Q1: SILOG | R1: =COUNTIF($C$110:$C$1203,"SILOG") -> 34 | S1: =IFERROR(VLOOKUP(J1,'IN OUT'!L:M,2,FALSE), "BELUM MASUK") -> BELUM MASUK
A2: DATE | B2: =TODAY() -> 45977 | E2: TRUCK TYPE | H2: PLAN AREA | I2: QTY TRUCK | J2: TONASE (MT) | Q2: SIBA | R2: =COUNTIF($C$110:$C$1203,"SIBA") -> 6
A3: TRUCK PLAN | B3: =SUM(I217:I1317) -> 43 | C3: *NEXTDAY 4 *AMBIL SENDIRI 3 *CROVER 4 | E3: TRAILER | F3: =SUMIF(H217:H1223, "TRAILER", I217:I1222) -> 11 | H3: JABODETABEK | I3: =COUNTIF(F217:F1223, "JABODETABEK") -> 34 | J3: =SUMIF(F217:F1223, "JABODETABEK", G217:G1223) -> 914641.18 | Q3: YUSHAR | R3: =COUNTIF($C$110:$C$1203,"YUSHAR") -> 18
A4: TRUCK AVAILABLE | B4: =SUM(J217:J1351) -> 38 | E4: TRONTON | F4: =SUMIF(H217:H1224, "TRONTON", I217:I1223) -> 32 | H4: JAWA TENGAH | I4: =COUNTIF($F$217:F1224, "JAWA TENGAH") -> 1 | J4: =SUMIF(F217:F1224, "JAWA TENGAH", G217:G1224) -> 30630.186 | Q4: BRJ | R4: =COUNTIF($C$110:$C$1203,"BRJ") -> 10
A5: SUDAH MASUK | B5: =COUNTIF(K217:K1200,"MASUK") -> 32 | E5: TOTAL | F5: =SUBTOTAL(9,F3:F4) -> 43 | H5: JAWA TIMUR | I5: =COUNTIF($F$217:F1225, "JAWA TIMUR") -> 8 | J5: =SUMIF(F217:F1225, "JAWA TIMUR", G217:G1225) -> 290630.1 | Q5: ALIEF | R5: =COUNTIF($C$110:$C$1203,"ALIEF") -> 35
A6: BELUM MASUK | B6: =COUNTIF(K217:K1200,"BELUM MASUK") -> 11 | E6: CARRY OVER 4 | F6: =G235+G258+G260+G261 -> 104713.92 | H6: TOTAL PLAN | I6: =SUM(I3:I5) -> 43 | J6: =SUM(J3:J5) -> 1235901.5 | Q6: ELANG | R6: =COUNTIF($C$110:$C$1203,"ELANG") -> 4
A7: KURANG TRUCK | B7: =B3-B4 -> 5 | C7: *3TRAILER *2TRONTON | E7: AMBIL SENDIRI 3 | F7: =G244+G245+G247 -> 108364.06 | Q7: CGL | R7: =COUNTIF($C$110:$C$1203,"CGL") -> 1
E8: NEXT DAY 4 | F8: =G262+G264+G265+G266 -> 163880.42 | Q8: *AKTUAL | R8: =SUM(R1:R7) -> 108
A11: Tanggal | B11: Delivery | C11: Vendor | D11: SN | E11: Name ship-to party | F11: AREA | G11: TOTAL WEIGHT | H11: TRUCK TYPE | I11: QTY KEBUTUHAN | J11: KETERSEDIAAN | K11: GATE IN | L11: Date MLS
A12: 01.09.2025 | B12: 3331548306 | C12: ETI | D12: 24140272 | E12: PT. KATI KARTIKA MURNI CIKARANG | F12: JABODETABEK | G12: 25 | H12: TRONTON | I12: 1 | J12: 1
A13: 01.09.2025 | B13: 3331548307 | C13: CGL | D13: 24140273 | E13: PT. KATI KARTIKA MURNI CIKARANG | F13: JABODETABEK | G13: 25 | H13: TRONTON | I13: 1 | J13: 1
A14: 01.09.2025 | B14: 3331547906 | C14: ALIEF | D14: 24140274 | E14: PT. DAYACIPTA KEMASINDO (GD) KARAWANG | F14: JABODETABEK | G14: 25 | H14: TRONTON | I14: 1 | J14: 1
A15: 01.09.2025 | B15: 3331548297 | C15: ALIEF | D15: 24140275 | E15: PT. DAYACIPTA KEMASINDO (GD) KARAWANG | F15: JABODETABEK | G15: 25 | H15: TRONTON | I15: 1 | J15: 1
A16: 02.09.2025 | B16: 3331548390 | C16: ALIEF | D16: 24140284 | E16: PT. DAYACIPTA KEMASINDO (GD) | F16: JABODETABEK | G16: 25 | H16: TRONTON | I16: 1 | J16: 1
A17: 02.09.2025 | B17: 3331548324 | C17: ETI | D17: 24140281 | E17: PT. APP PURINUSA EKAPERSADA SUBANG | F17: JABODETABEK | G17: 25 | H17: TRONTON | I17: 1 | J17: 1
A18: 01.09.2025 | B18: 3331548346 | E18: PT. APP PURINUSA EKAPERSADA | F18: JABODETABEK | G18: 25 | H18: TRONTON | I18: 1 | J18: 1
A19: 01.09.2025 | B19: 3331548331 | C19: CGL | D19: 24140277 | E19: PT. APP PURINUSA EKAPERSADA SUBANG | F19: JABODETABEK | G19: 25 | H19: TRONTON | I19: 1 | J19: 1
A20: 01.09.2025 | B20: 3331548348 | C20: ALIEF | D20: 24140279 | E20: PT. APP PURINUSA EKAPERSADA BANDUNG | F20: JABODETABEK | G20: 25 | H20: TRONTON | I20: 1 | J20: 1
A21: 01.09.2025 | B21: 3331548351 | C21: SILOG | D21: 24140280 | E21: DAYACIPTA KEMASINDO, PT (GD) Cibitung | F21: JABODETABEK | G21: 25 | H21: TRONTON | I21: 1 | J21: 1
A22: 02.09.2025 | B22: 3331548298 | C22: SILOG | D22: 24140282 | E22: PT DAYACIPTA KEMASINDO TANGERANG | F22: JABODETABEK | G22: 25 | H22: TRONTON | I22: 1 | J22: 1
A23: 01.09.2025 | B23: 3331547489 | C23: ALIEF | D23: 24140283 | E23: MULTI ARTHA ABADI, PT | F23: JABODETABEK | G23: 25 | H23: TRONTON | I23: 1 | J23: 1
A24: 01.09.2025 | B24: 3331548380 | E24: MULTI ARTHA ABADI, PT | F24: JABODETABEK | G24: 25 | H24: TRONTON | I24: 1 | J24: 1
A25: 02.09.2025 | B25: 3331548645 | C25: ALIEF | D25: 24140302 | E25: PT.SANTOSO JAWI (GD) SIDOARJO | F25: JAWA TIMUR | G25: 26525 | H25: TRONTON | I25: 1 | J25: 1
A26: 02.09.2025 | B26: 3331548670 | C26: ALIEF | D26: 24140304 | E26: PT. APP PURINUSA EKAPERSADA BANDUNG | F26: JABODETABEK | G26: 13000 | H26: TRONTON | I26: 1 | J26: 1
A27: 02.09.2025 | B27: 3331548667 | C27: ALIEF | E27: PT. APP PURINUSA EKAPERSADA | F27: JABODETABEK | G27: 11348 | H27: TRONTON | I27: 1 | J27: 1
A28: 02.09.2025 | B28: 3331548673 | C28: ALIEF | D28: 24140290 | E28: PT. KATI KARTIKA MURNI CIKARANG | F28: JABODETABEK | G28: 24763 | H28: TRONTON | I28: 1 | J28: 1
A29: 02.09.2025 | B29: 3331548675 | C29: ALIEF | D29: 24140291 | E29: PT. APP PURINUSA EKAPERSADA | F29: JABODETABEK | G29: 22060 | H29: TRONTON | I29: 1 | J29: 1
A30: 01.09.2025 | B30: 3331548333 | C30: ALIEF | D30: 24140295 | E30: PT. APP PURINUSA EKAPERSADA | F30: JABODETABEK | G30: 22060 | H30: TRONTON | I30: 1 | J30: 1
A31: 02.09.2025 | B31: 3331548732 | C31: BRJ | D31: 24140296 | E31: PT. APP PURINUSA EKAPERSADA DEMAK | F31: JAWA TENGAH | G31: 33872 | H31: TRAILER | I31: 1 | J31: 1
A32: 02.09.2025 | B32: 3331548736 | C32: BRJ | D32: 24140297 | E32: PT. APP PURINUSA EKAPERSADA DEMAK | F32: JAWA TENGAH | G32: 44529 | H32: TRAILER | I32: 1 | J32: 1
A33: 02.09.2025 | B33: 3331548741 | C33: BRJ | D33: 24140298 | E33: PT. APP PURINUSA EKAPERSADA DEMAK | F33: JAWA TENGAH | G33: 45726 | H33: TRAILER | I33: 1 | J33: 1
A34: 02.09.2025 | B34: 3331548746 | C34: BRJ | D34: 24140299 | E34: PT. APP PURINUSA EKAPERSADA SEMARANG | F34: JAWA TENGAH | G34: 37035 | H34: TRAILER | I34: 1 | J34: 1
A35: 02.09.2025 | B35: 3331548749 | C35: BRJ | D35: 24140300 | E35: PT. APP PURINUSA EKAPERSADA SEMARANG | F35: JAWA TENGAH | G35: 33812 | H35: TRAILER | I35: 1 | J35: 1
A36: 02.09.2025 | B36: 3331548756 | C36: SIBA | D36: 24140301 | E36: PT. APP PURINUSA EKAPERSADA SEMARANG | F36: JAWA TENGAH | G36: 34290 | H36: TRAILER | I36: 1 | J36: 1
A37: 02.09.2025 | B37: 3331548760 | C37: ALIEF | D37: 24140303 | E37: PT. KEMASAN INDAH SEJAHTERA | F37: JABODETABEK | G37: 13963 | H37: TRONTON | I37: 1 | J37: 1
A38: 02.09.2025 | B38: 3331548761 | E38: PT. KEMASAN INDAH SEJAHTERA | F38: JABODETABEK | G38: 10480 | H38: TRONTON | I38: 1 | J38: 1
A39: 02.09.2025 | B39: 3331548736 | C39: BRJ | D39: 24140297 | E39: PT. APP PURINUSA EKAPERSADA DEMAK | F39: JAWA TENGAH | G39: 44529 | H39: TRAILER | I39: 1 | J39: 1 | K39: 0.17986111 | L39: 0.44444444
A40: 02.09.2025 | B40: 3331548749 | C40: ETI | D40: 24140300 | E40: PT. APP PURINUSA EKAPERSADA BAWEN | F40: JAWA TENGAH | G40: 35775.372 | H40: TRAILER | I40: 1 | J40: 1 | K40: =IFERROR(VLOOKUP(B40,'IN OUT'!F:G,2,FALSE), "BELUM MASUK") -> BELUM MASUK | L40: 0.090277778
A41: 02.09.2025 | B41: 3331548756 | C41: SIBA SURYA | D41: 24140301 | E41: PT. APP PURINUSA EKAPERSADA | F41: JAWA TENGAH | G41: 34495.741 | H41: TRAILER | I41: 1 | J41: 1 | K41: =IFERROR(VLOOKUP(B41,'IN OUT'!F:G,2,FALSE), "BELUM MASUK") -> BELUM MASUK | L41: -
A42: 03.09.2025 | B42: 3331548394 | C42: ALIEF | D42: 24140305 | E42: PT. HEXA PRIMA PERSADA TGR | F42: JABODETABEK | G42: 26626.47 | H42: TRONTON | I42: 1 | J42: 1 | K42: =IFERROR(VLOOKUP(B42,'IN OUT'!F:G,2,FALSE), "BELUM MASUK") -> BELUM MASUK | L42: 0.84027778
...

Sheet 12.09.25
A1: ALL PLAN TODAY | B1: =TODAY() -> 45977 | D1: PLANNING | E1: JAM 7 PAGI - JAM 3 SORE | H1: PLANNING | I1: NEXT DAY | K1: ***CANCEL DN 3331551460, 3331548644 (JASKIN), 458, 459, 466, 468, 469, 492*** (TJIWI KIMIA) | P1: SILOG | Q1: =COUNTIF($C$20:$C$1019,"SILOG") -> 16 | R1: =IFERROR(VLOOKUP(J1,'IN OUT'!L:M,2,FALSE), "BELUM MASUK") -> BELUM MASUK
D2: PLAN AREA | E2: QTY TRUCK | F2: TONASE (MT) | H2: PLAN AREA | I2: QTY TRUCK | J2: TONASE (MT) | P2: SIBA | Q2: =COUNTIF($C$20:$C$1019,"SIBA") -> 0
A3: ALL PLAN TODAY | B3: =SUM(I20:I1133) -> 71 | D3: JABODETABEK | E3: =COUNTIF(F20:F1039,"JABODETABEK") -> 31 | F3: =SUMIF(F20:F1039, "JABODETABEK", G20:G1039) -> 814089.51 | H3: JABODETABEK | I3: {=SUMPRODUCT(--(RIGHT(F30:F1036,20)="JABODETABEK NEXT DAY"))} -> 18 | J3: =SUMIF(F32:F1039, "JABODETABEK NEXT DAY", G32:G1039) -> 467459.55 | P3: YUSHAR | Q3: =COUNTIF($C$20:$C$1019,"YUSHAR") -> 6
A4: TRUCK AVAILABLE | B4: =SUM(J20:J1167) -> 70 | D4: JAWA TENGAH | E4: =COUNTIF(F20:F1040, "JAWA TENGAH") -> 0 | F4: =SUMIF(F20:F1040, "JAWA TENGAH", G20:G1040) -> 0 | H4: JAWA TENGAH | I4: {=SUMPRODUCT(--(RIGHT(F31:F1037,20)="JAWA TENGAH NEXT DAY"))} -> 1 | J4: =SUMIF(F32:F1040, "JAWA TENGAH NEXT DAY", G32:G1040) -> 24487.83 | P4: BRJ | Q4: =COUNTIF($C$20:$C$1019,"BRJ") -> 3
A5: SUDAH MASUK | B5: =COUNTIF(K20:K1016,"MASUK") -> 76 | D5: JAWA TIMUR | E5: =COUNTIF(F20:F1041, "JAWA TIMUR") -> 6 | F5: =SUMIF(F20:F1041, "JAWA TIMUR", G20:G1041) -> 235419.42 | H5: JAWA TIMUR | I5: {=SUMPRODUCT(--(RIGHT(F32:F1038,20)="JAWA TIMUR NEXT DAY"))} -> 11 | J5: =SUMIF(F32:F1041, "JAWA TIMUR NEXT DAY", G32:G1041) -> 432320.15 | P5: ALIEF | Q5: =COUNTIF($C$20:$C$1019,"ALIEF") -> 15
A6: BELUM MASUK | B6: =COUNTIF(K20:K1016,"BELUM MASUK") -> 0 | D6: TOTAL PLAN JAM 7-3 | E6: =SUM(E3:E5) -> 37 | F6: =SUM(F3:F5) -> 1049508.9 | H6: TOTAL PLAN NEXT DAY | I6: =SUM(I3:I5) -> 30 | J6: =SUM(J3:J5) -> 924267.53 | P6: ELANG | Q6: =COUNTIF($C$20:$C$1019,"ELANG") -> 1
A7: KURANG TRUCK | B7: =(B3-B4)-I10 -> -3 | P7: CGL | Q7: =COUNTIF($C$20:$C$1019,"CGL") -> 0
D8: PLANNING | E8: DIATAS JAM 3 SORE | H8: PLANNING | I8: INTER ISLAND | P8: *AKTUAL | Q8: =SUM(Q1:Q7) -> 41
A9: TRUCK TYPE | D9: PLAN AREA | E9: QTY TRUCK | F9: TONASE (MT) | H9: PLAN AREA | I9: QTY TRUCK | J9: TONASE (MT)
A10: TRAILER | B10: =SUMIF($H$20:$H$1039, "TRAILER", $I$20:$I$1038) -> 21 | D10: JABODETABEK | E10: =COUNTIF(F82:F1046,"JABODETABEK") -> 7 | F10: =SUMIF(F83:F1046,"JABODETABEK", G83:G1046) -> 155115.6 | H10: BATAM | I10: =COUNTIF(F20:F1041,"INTERISLAND") -> 4 | J10: =SUMIF(F20:F1041,"INTERISLAND ",G20:G1041) -> 0
A11: TRONTON | B11: =SUMIF($H$20:$H$1040, "TRONTON", $I$20:$I$1039) -> 46 | D11: JAWA TENGAH | E11: =COUNTIF(F83:F1047,"JAWA TENGAH") -> 0 | F11: =SUMIF(F83:F1047, "JAWA TENGAH", G83:G1047) -> 0
A12: HC45 | B12: 4 | D12: JAWA TIMUR NEXTDAY | E12: =COUNTIF(F83:F1048, "JAWA TIMUR NEXT DAY") -> 2 | F12: =SUMIF(F83:F1048, "JAWA TIMUR NEXT DAY", G83:G1048) -> 71699.366 | H12: DELIVERY RESULT | S12: =29+29+4 -> 62
A13: CARRY OVER TONASE | B13: =$G$20+$G$25+$G$26+$G$27 -> 104713.92 | D13: TOTAL PLAN JAM 3 | E13: =SUM(E10:E12) -> 9 | F13: =SUM(F10:F12) -> 226814.96 | H13: PLAN AREA | I13: PLAN | J13: REALISASI
A14: CARRY OVER TRUCK | B14: 4 | H14: PLAN S/D JAM 3 | I14: =COUNTIF(F24:F1045,"INTERISLAND") -> 4 | J14: =SUMIF(F24:F1045,"INTERISLAND ",G24:G1045) -> 0
A15: AMBIL SENDIRI KEMARIN | B15: 3 | D15: ALL PLAN | E15: =E6+I6+I10 -> 71 | H15: PLAN NEXT DAY | I15: =COUNTIF(F25:F1046,"INTERISLAND") -> 4 | J15: =SUMIF(F25:F1046,"INTERISLAND ",G25:G1046) -> 0
A16: NEXT DAY KEMARIN | B16: 4 | D16: TOTAL MT | E16: =F6+J6 -> 1973776.5 | H16: PLAN INTER ISLAND | I16: =COUNTIF(F26:F1047,"INTERISLAND") -> 4 | J16: =SUMIF(F26:F1047,"INTERISLAND ",G26:G1047) -> 0
A17: AMBIL SENDIRI+NEXTDAY TON
A19: Tanggal | B19: Delivery | C19: Vendor | D19: SN | E19: Name ship-to party | F19: AREA | G19: TOTAL WEIGHT | H19: TRUCK TYPE | I19: QTY KEBUTUHAN | J19: KETERSEDIAAN | K19: GATE IN
A20: 11.09.2025 BLM GI CR OVER | B20: 3331551124 | C20: YUSHAR | D20: 24140469 | E20: PT. APP PURINUSA EKAPERSADA BANDUNG | F20: JABODETABEK | G20: 26578.017 | H20: =IF(G20>28000,"TRAILER","TRONTON") -> TRONTON | I20: 1 | J20: 1 | K20: MASUK
A21: 11.09.2025 AMBIL SENDIRI | B21: 3331551177 | C21: BRJ | D21: 24140477 | E21: PT KARYA INDAH MULTIGUNA AMBIL SENDIRI | F21: JABODETABEK | G21: 36297.486 | H21: =IF(G21>28000,"TRAILER","TRONTON") -> TRAILER | I21: 1 | J21: 1 | K21: MASUK
A22: 11.09.2025 AMBIL SENDIRI | B22: 3331551181 | C22: BRJ | D22: 24140479 | E22: PT KARYA INDAH MULTIGUNA AMBIL SENDIRI | F22: JABODETABEK | G22: =9471.49+25738.51 -> 35210 | H22: =IF(G22>28000,"TRAILER","TRONTON") -> TRAILER | I22: 1 | J22: 1 | K22: MASUK
A23: = | B23: 3331551215 | C23: = | D23: = | E23: = | F23: = | G23: = | H23: = | I23: = | J23: = | K23: MASUK
A24: 11.09.2025 AMBIL SENDIRI | B24: 3331551212 | C24: BRJ | D24: 24140480 | E24: PT KARYA INDAH MULTIGUNA AMBIL SENDIRI | F24: JABODETABEK | G24: 36856.57 | H24: =IF(G24>28000,"TRAILER","TRONTON") -> TRAILER | I24: 1 | J24: 1 | K24: MASUK
A25: 11.09.2025 BLM GI CR OVER | B25: 3331551283 | C25: YUSHAR | D25: 24140489 | E25: PT. PARAMITRA GUNAKARYA CEMERLANG | F25: JABODETABEK | G25: 24431.213 | H25: =IF(G25>28000,"TRAILER","TRONTON") -> TRONTON | I25: 1 | J25: 0 | K25: MASUK
A26: 11.09.2025 BLM GI CR OVER | B26: 3331551327 | C26: SILOG | D26: 24140493 | E26: PT. KEMASAN INDAH SEJAHTERA TGR | F26: JABODETABEK | G26: 26852.344 | H26: =IF(G26>28000,"TRAILER","TRONTON") -> TRONTON | I26: 1 | J26: 1 | K26: MASUK
A27: 11.09.2025 BLM GI CR OVER | B27: 3331551329 | C27: TFT | D27: 24140494 | E27: PT. KEMASAN INDAH SEJAHTERA TGR | F27: JABODETABEK | G27: 26852.344 | H27: =IF(G27>28000,"TRAILER","TRONTON") -> TRONTON | I27: 1 | J27: 1 | K27: MASUK
A28: 11.09.2025 | B28: 3331551328 | C28: SILOG | D28: 24140497 | E28: PT PABRIK KERTAS TJIWI KIMIA | F28: JAWA TIMUR | G28: 39334.6 | H28: =IF(G28>28000,"TRAILER","TRONTON") -> TRAILER | I28: 1 | J28: 1 | K28: MASUK
A29: 11.09.2025 | B29: 3331551336 | C29: KIM | D29: 24140496 | E29: PT PABRIK KERTAS TJIWI KIMIA | F29: JAWA TIMUR | G29: 39334.6 | H29: =IF(G29>28000,"TRAILER","TRONTON") -> TRAILER | I29: 1 | J29: 1 | K29: MASUK
A30: 11.09.2025 | B30: 3331551337 | C30: SILOG | D30: 24140498 | E30: PT PABRIK KERTAS TJIWI KIMIA | F30: JAWA TIMUR | G30: 43909.888 | H30: =IF(G30>28000,"TRAILER","TRONTON") -> TRAILER | I30: 1 | J30: 1 | K30: MASUK
A31: 11.09.2025 | B31: 3331551338 | C31: KIM | D31: 24140499 | E31: PT PABRIK KERTAS TJIWI KIMIA | F31: JAWA TIMUR | G31: 41301.33 | H31: =IF(G31>28000,"TRAILER","TRONTON") -> TRAILER | I31: 1 | J31: 1 | K31: MASUK
A32: 14.09.2025 NEXT DAY | B32: 3331551476 | C32: KIM | D32: 24140560 | E32: PT PABRIK KERTAS TJIWI KIMIA | F32: JAWA TIMUR NEXT DAY | G32: 39953.039 | H32: =IF(G32>28000,"TRAILER","TRONTON") -> TRAILER | I32: 1 | J32: 1 | K32: MASUK
A33: 14.09.2025 NEXT DAY | B33: 3331551479 | C33: KIM | D33: 24140561 | E33: PT PABRIK KERTAS TJIWI KIMIA | F33: JAWA TIMUR NEXT DAY | G33: 39910.033 | H33: =IF(G33>28000,"TRAILER","TRONTON") -> TRAILER | I33: 1 | J33: 1 | K33: MASUK
A34: 15.09.2025 NEXT DAY | B34: 3331551481 | C34: KIM | D34: 24140562 | E34: PT PABRIK KERTAS TJIWI KIMIA | F34: JAWA TIMUR NEXT DAY | G34: 39135.915 | H34: =IF(G34>28000,"TRAILER","TRONTON") -> TRAILER | I34: 1 | J34: 1 | K34: MASUK
A35: 15.09.2025 NEXT DAY | B35: 3331551485 | C35: KIM | D35: 24140563 | E35: PT PABRIK KERTAS TJIWI KIMIA | F35: JAWA TIMUR NEXT DAY | G35: 39135.915 | H35: =IF(G35>28000,"TRAILER","TRONTON") -> TRAILER | I35: 1 | J35: 1 | K35: MASUK
... A68: 15.09.2025 | B68: 3331551530 | C68: ALIEF | D68: 24140529 | E68: PT. APP PURINUSA EKAPERSADA SBG | F68: JABODETABEK | G68: 24685.229 | H68: =IF(G68>28000,"TRAILER","TRONTON") -> TRONTON | I68: 1 | J68: 1 | K68: MASUK
A69: 12.09.2025 | B69: 3331551526 | C69: ALIEF | D69: 24140530 | E69: PT. KEMASAN INDAH SEJAHTERA TGR | F69: JABODETABEK | G69: 25913.552 | H69: =IF(G69>28000,"TRAILER","TRONTON") -> TRONTON | I69: 1 | J69: 1 | K69: MASUK | O69: =22+36 -> 58
A70: 12.09.2025 | B70: 3331551534 | C70: TFT | D70: 24140531 | E70: PT. KEMASAN INDAH SEJAHTERA TGR | F70: JABODETABEK | G70: 24214.227 | H70: =IF(G70>28000,"TRAILER","TRONTON") -> TRONTON | I70: 1 | J70: 1 | K70: MASUK
A71: 14.09.2025 | B71: 3331551536 | C71: TFT | D71: 24140532 | E71: PT. KEMASAN INDAH SEJAHTERA TGR | F71: JABODETABEK | G71: 23884.459 | H71: =IF(G71>28000,"TRAILER","TRONTON") -> TRONTON | I71: 1 | J71: 1 | K71: MASUK
A72: 15.09.2025 | B72: 3331551538 | C72: ALIEF | D72: 24140533 | E72: PT. APP PURINUSA EKAPERSADA SBG | F72: JABODETABEK | G72: 24857.255 | H72: =IF(G72>28000,"TRAILER","TRONTON") -> TRONTON | I72: 1 | J72: 1 | K72: MASUK
A73: 13.09.2025 | B73: 3331551565 | C73: TPIL | D73: 24140546 | E73: PT. ASIA PAPERINDO PERKASA BATAM GB1 | F73: INTERISLAND | G73: =8978.55+10752.128+7534.374 -> 27265.052 | H73: HC45 | I73: 1 | J73: 1 | K73: MASUK
...

Sheet 15.09.25
A1: ALL PLAN TODAY | B1: =TODAY() -> 45977 | D1: PLANNING | E1: JAM 7 PAGI - JAM 3 SORE | H1: PLANNING | I1: NEXT DAY | P1: SILOG | Q1: =COUNTIF($C$20:$C$980,"SILOG") -> 14 | R1: =IFERROR(VLOOKUP(J1,'IN OUT'!L:M,2,FALSE), "BELUM MASUK") -> BELUM MASUK
D2: PLAN AREA | E2: QTY TRUCK | F2: TONASE (MT) | H2: PLAN AREA | I2: QTY TRUCK | J2: TONASE (MT) | P2: SIBA | Q2: =COUNTIF($C$20:$C$980,"SIBA") -> 1
A3: ALL PLAN TODAY | B3: =SUM(I20:I1094)+I10 -> 34 | D3: JABODETABEK | E3: =COUNTIF(F20:F1000,"JABODETABEK") -> 12 | F3: =SUMIF(F20:F1000, "JABODETABEK", G20:G1000) -> 299665.24 | H3: JABODETABEK | I3: {=SUMPRODUCT(--(RIGHT(F20:F997,20)="JABODETABEK NEXT DAY"))} -> 6 | J3: =SUMIF(F20:F1000, "JABODETABEK NEXT DAY", G20:G1000) -> 153094.09 | P3: YUSHAR | Q3: =COUNTIF($C$20:$C$980,"YUSHAR") -> 2
A4: TRUCK AVAILABLE | B4: =SUM(J20:J1128) -> 28 | D4: JAWA TENGAH | E4: =COUNTIF(F20:F1001, "JAWA TENGAH") -> 0 | F4: =SUMIF(F20:F1001, "JAWA TENGAH", G20:G1001) -> 0 | H4: JAWA TENGAH | I4: {=SUMPRODUCT(--(RIGHT(F34:F998,20)="JAWA TENGAH NEXT DAY"))} -> 5 | J4: =SUMIF(F34:F1001, "JAWA TENGAH NEXT DAY", G34:G1001) -> 152164.04 | P4: BRJ | Q4: =COUNTIF($C$20:$C$980,"BRJ") -> 0
A5: SUDAH MASUK | B5: =COUNTIF(K20:K977,"MASUK") -> 28 | D5: JAWA TIMUR | E5: =COUNTIF(F20:F1002, "JAWA TIMUR") -> 1 | F5: =SUMIF(F20:F1002, "JAWA TIMUR", G20:G1002) -> 44089.52 | H5: JAWA TIMUR | I5: {=SUMPRODUCT(--(RIGHT(F34:F999,20)="JAWA TIMUR NEXT DAY"))} -> 6 | J5: =SUMIF(F34:F1002, "JAWA TIMUR NEXT DAY", G34:G1002) -> 221715.93 | P5: ALIEF | Q5: =COUNTIF($C$20:$C$980,"ALIEF") -> 0
A6: BELUM MASUK | B6: =COUNTIF(K20:K977,"BELUM MASUK") -> 0 | D6: TOTAL PLAN JAM 7-3 | E6: =SUM(E3:E5) -> 13 | F6: =SUM(F3:F5) -> 343754.76 | H6: TOTAL PLAN NEXT DAY | I6: =SUM(I3:I5) -> 17 | J6: =SUM(J3:J5) -> 526974.06 | P6: ELANG | Q6: =COUNTIF($C$20:$C$980,"ELANG") -> 1
A7: KURANG TRUCK | B7: =(B3-B4)-I10 -> 2 | C7: *PEP BAWEN TRONTON 2 TRAILER 2 | P7: CGL | Q7: =COUNTIF($C$20:$C$980,"CGL") -> 0
D8: PLANNING | E8: DIATAS JAM 3 SORE | H8: PLANNING | I8: INTER ISLAND | P8: *AKTUAL | Q8: =SUM(Q1:Q7) -> 18
A9: TRUCK TYPE | D9: PLAN AREA | E9: QTY TRUCK | F9: TONASE (MT) | H9: PLAN AREA | I9: QTY TRUCK | J9: TONASE (MT)
A10: TRAILER | B10: =SUMIF($H$20:$H$1000, "TRAILER", $I$20:$I$999) -> 9 | D10: JABODETABEK | E10: =COUNTIF(F45:F1007,"JABODETABEK") -> 0 | F10: =SUMIF(F114:F1007,"JABODETABEK", G34:G1007) -> 0 | H10: BATAM | I10: 4 | J10: =SUMIF(F20:F1002,"INTERISLAND ",G20:G1002) -> 0
A11: TRONTON | B11: =SUMIF($H$20:$H$1001, "TRONTON", $I$20:$I$1000) -> 21 | D11: JAWA TENGAH | E11: =COUNTIF(F45:F1008,"JAWA TENGAH") -> 0 | F11: =SUMIF(F34:F1008, "JAWA TENGAH", G34:G1008) -> 0
A12: HIGH CUBE 40 | B12: 0 | D12: JAWA TIMUR NEXTDAY | E12: =COUNTIF(F45:F1009, "JAWA TIMUR NEXT DAY") -> 6 | F12: =SUMIF(F34:F1009, "JAWA TIMUR NEXT DAY", G34:G1009) -> 221715.93 | S12: =29+29+4 -> 62
A13: CARRY OVER TONASE | B13: 0 | D13: TOTAL PLAN JAM 3 | E13: =SUM(E10:E12) -> 6 | F13: =SUM(F10:F12) -> 221715.93
A14: CARRY OVER TRUCK | B14: 0
A15: AMBIL SENDIRI KEMARIN | B15: 0 | D15: ALL PLAN | E15: =E6+I6+I10 -> 34
A16: NEXT DAY KEMARIN | B16: 0 | D16: TOTAL MT | E16: =F6+J6 -> 870728.81
A17: AMBIL SENDIRI+NEXTDAY TON
A19: Tanggal | B19: Delivery | C19: Vendor | D19: SN | E19: Name ship-to party | F19: AREA | G19: TOTAL WEIGHT | H19: TRUCK TYPE | I19: QTY KEBUTUHAN | J19: KETERSEDIAAN | K19: GATE IN
A20: 15.09.2025 | B20: 3331552223 | C20: SILOG | D20: 24140571 | E20: PT. KATI KARTIKA MURNI CIKARANG | F20: JABODETABEK | G20: 25721.801 | H20: =IF(G90>28000,"TRAILER","TRONTON") -> TRONTON | I20: 1 | J20: 1 | K20: MASUK
A21: 15.09.2025 | B21: 3331552226 | C21: SILOG | D21: 24140572 | E21: PT. KATI KARTIKA MURNI TANGERANG | F21: JABODETABEK | G21: 27180.108 | H21: =IF(G91>28000,"TRAILER","TRONTON") -> TRONTON | I21: 1 | J21: 1 | K21: MASUK
A22: 15.09.2025 | B22: 3331552227 | C22: SILOG | D22: 24140573 | E22: PT. KATI KARTIKA MURNI TANGERANG | F22: JABODETABEK | G22: 26794.056 | H22: =IF(G91>28000,"TRAILER","TRONTON") -> TRONTON | I22: 1 | J22: 1 | K22: MASUK
A23: 15.09.2025 | B23: 3331552233 | C23: SILOG | D23: 24140574 | E23: PT. APP PURINUSA EKAPERSADA SBG | F23: JABODETABEK | G23: 26492.004 | H23: =IF(G92>28000,"TRAILER","TRONTON") -> TRONTON | I23: 1 | J23: 1 | K23: MASUK
A24: 15.09.2025 NEXT DAY | B24: 3331551987 | C24: SILOG | D24: 24140575 | E24: PT. APP PURINUSA EKAPERSADA BDG | F24: JABODETABEK NEXT DAY | G24: =20213.558+7524.88 -> 27738.438 | H24: =IF(G93>28000,"TRAILER","TRONTON") -> TRONTON | I24: 1 | J24: 1 | K24: MASUK
A25: = | B25: 3331551996 | C25: = | D25: = | E25: = | F25: = | G25: = | H25: = | I25: = | J25: = | K25: =
A26: 15.09.2025 NEXT DAY | B26: 3331551959 | C26: SILOG | D26: 24140576 | E26: PT. APP PURINUSA EKAPERSADA BDG | F26: JABODETABEK NEXT DAY | G26: =1240.398+20471.094 -> 21711.492 | H26: =IF(G95>28000,"TRAILER","TRONTON") -> TRONTON | I26: 1 | J26: 1 | K26: MASUK
A27: = | B27: 3331552012 | C27: = | D27: = | E27: = | F27: = | G27: = | H27: = | I27: = | J27: = | K27: =
A28: 15.09.2025 NEXT DAY | B28: 3331552232 | C28: SILOG | D28: 24140577 | E28: PT. APP PURINUSA EKAPERSADA BDG | F28: JABODETABEK NEXT DAY | G28: =23002.19+2666.906 -> 25669.096 | H28: =IF(G97>28000,"TRAILER","TRONTON") -> TRONTON | I28: 1 | J28: 1 | K28: MASUK
A29: = | B29: 3331552234 | C29: = | D29: = | E29: = | F29: = | G29: = | H29: = | I29: = | J29: = | K29: =
A30: 15.09.2025 NEXT DAY | B30: 3331551945 | C30: SILOG | D30: 24140578 | E30: PT. APP PURINUSA EKAPERSADA BDG | F30: JABODETABEK NEXT DAY | G30: 23525.31 | H30: =IF(G99>28000,"TRAILER","TRONTON") -> TRONTON | I30: 1 | J30: 1 | K30: MASUK
A31: 15.09.2025 NEXT DAY | B31: 3331552244 | C31: SILOG | D31: 24140579 | E31: PT. APP PURINUSA EKAPERSADA BDG | F31: JABODETABEK NEXT DAY | G31: 28645.85 | H31: =IF(G100>28000,"TRAILER","TRONTON") -> TRONTON | I31: 1 | J31: 1 | K31: MASUK
A32: 15.09.2025 | B32: 3331552240 | C32: TFT | D32: 24140580 | E32: PT. PARAMITRA GUNAKARYA CEMERLANG BOGOR | F32: JABODETABEK | G32: 24854.774 | H32: =IF(G101>28000,"TRAILER","TRONTON") -> TRONTON | I32: 1 | J32: 1 | K32: MASUK
A33: 15.09.2025 | B33: 3331552242 | C33: TFT | D33: 24140581 | E33: PT. PARAMITRA GUNAKARYA CEMERLANG BOGOR | F33: JABODETABEK | G33: 24032.055 | H33: =IF(G102>28000,"TRAILER","TRONTON") -> TRONTON | I33: 1 | J33: 1 | K33: MASUK
A34: 15.09.2025 | B34: 3331552245 | C34: TFT | D34: 24140582 | E34: PT. PARAMITRA GUNAKARYA CEMERLANG BOGOR | F34: JABODETABEK | G34: =18189.441+5375.813 -> 23565.254 | H34: =IF(G103>28000,"TRAILER","TRONTON") -> TRONTON | I34: 1 | J34: 1 | K34: MASUK
A35: = | B35: 3331552249 | C35: = | D35: = | E35: = | F35: = | G35: = | H35: = | I35: = | J35: = | K35: =
A36: 15.09.2025 | B36: 3331552230 | C36: TFT | D36: 24140583 | E36: DAYACIPTA KEMASINDO, PT (GD) | F36: JABODETABEK | G36: =2056.23+18462.113 -> 20518.343 | H36: =IF(Table13[[#This Row],[TOTAL WEIGHT]]>28000,"TRAILER","TRONTON") -> TRONTON | I36: 1 | J36: 1 | K36: MASUK
A37: = | B37: 3331552239 | C37: = | D37: = | E37: = | F37: = | G37: = | H37: = | I37: = | J37: = | K37: =
A38: 15.09.2025 | B38: 3331552270 | C38: SILOG | D38: 24140584 | E38: PT. APP PURINUSA EKAPERSADA SBG | F38: JABODETABEK | G38: 24255.667 | H38: TRONTON | I38: 1 | J38: 1 | K38: MASUK
A39: 15.09.2025 | B39: 3331552299 | C39: YUSHAR | D39: 24140586 | E39: PT. APP PURINUSA EKAPERSADA SBG | F39: JABODETABEK | G39: 25803.9 | H39: =IF(Table13[[#This Row],[TOTAL WEIGHT]]>28000,"TRAILER","TRONTON") -> TRONTON | I39: 1 | J39: 1 | K39: MASUK
A40: 15.09.2025 | B40: 3331552315 | C40: YUSHAR | D40: 24140587 | E40: CIPTA MULTI BUANA PERKASA, PT | F40: JABODETABEK | G40: 25945.373 | H40: =IF(Table13[[#This Row],[TOTAL WEIGHT]]>28000,"TRAILER","TRONTON") -> TRONTON | I40: 1 | J40: 1 | K40: MASUK
A41: 15.09.2025 | B41: 3331552316 | C41: RPK | D41: 24140588 | E41: CIPTA MULTI BUANA PERKASA, PT | F41: JABODETABEK | G41: 24501.9 | H41: =IF(Table13[[#This Row],[TOTAL WEIGHT]]>28000,"TRAILER","TRONTON") -> TRONTON | I41: 1 | J41: 1 | K41: MASUK
...

Sheet IN OUT
A1: Gudang | B1: Gudang FG BM3
A3: SJ | B3: Tanggal Timbang 1 | C3: Tanggal Timbang 2 | F3: DEL NUMBER | G3: DATE IN | H3: DATE OUT
A4: 3331550557 | B4: 45910.317 | C4: 45910.668 | F4: =A4 -> 3331550557 | G4: =B4 -> 45910.317 | H4: =C4 -> 45910.668
A5: 3331550708 | B5: 45910.458 | C5: (blank) | F5: =A5 -> 3331550708 | G5: =B5 -> 45910.458 | H5: =C5 -> (blank)
A6: 3331550709 | B6: 45910.468 | C6: (blank) | F6: =A6 -> 3331550709 | G6: =B6 -> 45910.468 | H6: =C6 -> (blank)
A7: 3331550712 | B7: 45910.491 | C7: (blank) | F7: =A7 -> 3331550712 | G7: =B7 -> 45910.491 | H7: =C7 -> (blank)
A8: 3331550726 | B8: 45910.494 | C8: (blank) | F8: =A8 -> 3331550726 | G8: =B8 -> 45910.494 | H8: =C8 -> (blank)
A9: 3331550710 | B9: 45910.498 | C9: (blank) | F9: =A9 -> 3331550710 | G9: =B9 -> 45910.498 | H9: =C9 -> (blank)
A10: 3331550703 | B10: 45910.499 | C10: (blank) | F10: 3331550011 | G10: =B10 -> 45910.499 | H10: =C10 -> (blank)
A11: 3331550704 | B11: 45910.501 | C11: (blank) | F11: 3331550021 | G11: =B12 -> 45910.576 | H11: =C12 -> (blank)
A12: 3331550733 | B12: 45910.576 | C12: (blank) | F12: =A10 -> 3331550703 | G12: =B10 -> 45910.499 | H12: =C13 -> (blank)
A13: 3331550722; 3331550725 | B13: 45910.578 | C13: (blank) | F13: =A11 -> 3331550704 | G13: =B11 -> 45910.501
A14: 3331550428 | B14: 45910.582 | C14: (blank) | F14: =A12 -> 3331550733 | G14: =B12 -> 45910.576
A15: 3331550772 | B15: 45910.644 | C15: (blank) | F15: =A13 -> 3331550722; 3331550725 | G15: =B13 -> 45910.578
A16: Grand Total | F16: =A14 -> 3331550428 | G16: =B14 -> 45910.582
F17: =A15 -> 3331550772 | G17: =B15 -> 45910.644

Sheet OVERNIGHT 
B2: Report Date | C2: DN | D2: Customer | E2: Area | F2: Transporter | G2: Nopol | H2: Arrived Date
B3: 45896 | C3: 3331546308 | D3: PT. KATI KARTIKA MURNI | E3: TANGERANG | F3: CGL | G3: B 9086 PYX | H3: 45895
B4: 45896 | C4: 3331546393 | D4: PT. PARAMITRA GUNAKARYA CEMERLANG | E4: SENTUL | F4: DUNEX | G4: B 9969 UEV | H4: 45895
B5: 45896 | C5: 3331546411 | D5: PT. PARAMITRA GUNAKARYA CEMERLANG | E5: SENTUL | F5: DUNEX | G5: B 9897 UXU | H5: 45895
B6: 45896 | C6: 3331546395 | D6: PT. PARAMITRA GUNAKARYA CEMERLANG | E6: SENTUL | F6: DUNEX | G6: B 9971 UEV | H6: 45895
B7: 45896 | C7: 3331546276 | D7: KIS TANGERANG | E7: SENTUL | F7: RPK | G7: T 8034 EL | H7: 45895
B8: 45896 | C8: 3331546383 | D8: PT. PARAMITRA GUNAKARYA CEMERLANG | E8: SENTUL | F8: RPK | G8: B 9089 SEU | H8: 45895
B9: 01.09.2025 | C9: 3331548307 | D9: PT. KATI KARTIKA MURNI CIKARANG | E9: 24140273 | F9: CGL

Sheet PROJECT
Q1: SILOG | R1: =COUNTIF($C$109:$C$1136,"SILOG") -> 19 | S1: =IFERROR(VLOOKUP(J1,'IN OUT'!L:M,2,FALSE), "BELUM MASUK") -> BELUM MASUK
A2: DATE | B2: =TODAY() -> 45977 | E2: TRUCK TYPE | H2: PLAN AREA | I2: QTY TRUCK | J2: TONASE (MT) | Q2: SIBA | R2: =COUNTIF($C$109:$C$1136,"SIBA") -> 5
A3: TRUCK PLAN | B3: =SUM(I174:I250) -> 25 | C3: *Next Day 3 DN 3 TRAILER | E3: TRAILER | F3: =SUMIF(H174:H1156, "TRAILER", I174:I1155) -> 4 | H3: JABODETABEK | I3: =COUNTIF(F174:F1156, "JABODETABEK") -> 21 | J3: =SUMIF(F174:F1156, "JABODETABEK", G174:G1156) -> 504047.4 | Q3: YUSHAR | R3: =COUNTIF($C$109:$C$1136,"YUSHAR") -> 11
A4: TRUCK AVAILABLE | B4: =SUM(J174:J284) -> 21 | E4: TRONTON | F4: =SUMIF(H174:H1157, "TRONTON", I174:I1156) -> 21 | H4: JAWA TENGAH | I4: =COUNTIF($F$174:F1157, "JAWA TENGAH") -> 3 | J4: =SUMIF(F174:F1157, "JAWA TENGAH", G174:G1157) -> 99624.181 | Q4: BRJ | R4: =COUNTIF($C$109:$C$1136,"BRJ") -> 6
A5: SUDAH MASUK | B5: =COUNTIF(K174:K1133,"MASUK") -> 10 | H5: JAWA TIMUR | I5: =COUNTIF($F$174:F1158, "JAWA TIMUR") -> 1 | J5: =SUMIF(F174:F1158, "JAWA TIMUR", G174:G1158) -> 46674.21 | Q5: ALIEF | R5: =COUNTIF($C$109:$C$1136,"ALIEF") -> 21
A6: BELUM MASUK | B6: =COUNTIF(K174:K1133,"BELUM MASUK") -> 16 | H6: TOTAL PLAN | I6: =SUM(I3:I5) -> 25 | J6: =SUM(J3:J5) -> 650345.79 | K6: *NEXT DAY 3 Dn (3 TRAILER ) | Q6: ELANG | R6: =COUNTIF($C$109:$C$1136,"ELANG") -> 2
A7: KURANG TRUCK | B7: =B3-B4 -> 4 | C7: *TRONTON | K7: =SUM($G$174:$G$176) -> 112376.07 | Q7: CGL | R7: =COUNTIF($C$109:$C$1136,"CGL") -> 1
Q8: *AKTUAL | R8: =SUM(R1:R7) -> 65
A10: Tanggal | B10: Delivery | C10: Vendor | D10: SN | E10: Name ship-to party | F10: AREA | G10: TOTAL WEIGHT | H10: TRUCK TYPE | I10: QTY KEBUTUHAN | J10: KETERSEDIAAN | K10: GATE IN | L10: Date
A11: 01.09.2025 | B11: 3331548306 | C11: ETI | D11: 24140272 | E11: PT. KATI KARTIKA MURNI CIKARANG | F11: JABODETABEK | G11: 25 | H11: TRONTON | I11: 1 | J11: 1
A12: 01.09.2025 | B12: 3331548307 | C12: CGL | D12: 24140273 | E12: PT. KATI KARTIKA MURNI CIKARANG | F12: JABODETABEK | G12: 25 | H12: TRONTON | I12: 1 | J12: 1
A13: 01.09.2025 | B13: 3331547906 | C13: ALIEF | D13: 24140274 | E13: PT. DAYACIPTA KEMASINDO (GD) KARAWANG | F13: JABODETABEK | G13: 25 | H13: TRONTON | I13: 1 | J13: 1
A14: 01.09.2025 | B14: 3331548297 | C14: ALIEF | D14: 24140275 | E14: PT. DAYACIPTA KEMASINDO (GD) KARAWANG | F14: JABODETABEK | G14: 25 | H14: TRONTON | I14: 1 | J14: 1
A15: 02.09.2025 | B15: 3331548390 | C15: ALIEF | D15: 24140284 | E15: PT. DAYACIPTA KEMASINDO (GD) | F15: JABODETABEK | G15: 25 | H15: TRONTON | I15: 1 | J15: 1
A16: 02.09.2025 | B16: 3331548324 | C16: ETI | D16: 24140281 | E16: PT. APP PURINUSA EKAPERSADA SUBANG | F16: JABODETABEK | G16: 25 | H16: TRONTON | I16: 1 | J16: 1
A17: 01.09.2025 | B17: 3331548346 | E17: PT. APP PURINUSA EKAPERSADA | F17: JABODETABEK | G17: 25 | H17: TRONTON | I17: 1 | J17: 1
A18: 01.09.2025 | B18: 3331548331 | C18: CGL | D18: 24140277 | E18: PT. APP PURINUSA EKAPERSADA SUBANG | F18: JABODETABEK | G18: 25 | H18: TRONTON | I18: 1 | J18: 1
A19: 01.09.2025 | B19: 3331548348 | C19: ALIEF | D19: 24140279 | E19: PT. APP PURINUSA EKAPERSADA BANDUNG | F19: JABODETABEK | G19: 25 | H19: TRONTON | I19: 1 | J19: 1
A20: 01.09.2025 | B20: 3331548351 | C20: SILOG | D20: 24140280 | E20: DAYACIPTA KEMASINDO, PT (GD) Cibitung | F20: JABODETABEK | G20: 25 | H20: TRONTON | I20: 1 | J20: 1
A21: 02.09.2025 | B21: 3331548298 | C21: SILOG | D21: 24140282 | E21: PT DAYACIPTA KEMASINDO TANGERANG | F21: JABODETABEK | G21: 25 | H21: TRONTON | I21: 1 | J21: 1
A22: 01.09.2025 | B22: 3331547489 | C22: ALIEF | D22: 24140283 | E22: MULTI ARTHA ABADI, PT | F22: JABODETABEK | G22: 25 | H22: TRONTON | I22: 1 | J22: 1
A23: 01.09.2025 | B23: 3331548380 | E23: MULTI ARTHA ABADI, PT | F23: JABODETABEK | G23: 25 | H23: TRONTON | I23: 1 | J23: 1
A24: 02.09.2025 | B24: 3331548645 | C24: ALIEF | D24: 24140302 | E24: PT.SANTOSO JAWI (GD) SIDOARJO | F24: JAWA TIMUR | G24: 26525 | H24: TRONTON | I24: 1 | J24: 1
A25: 02.09.2025 | B25: 3331548670 | C25: ALIEF | D25: 24140304 | E25: PT. APP PURINUSA EKAPERSADA BANDUNG | F25: JABODETABEK | G25: 13000 | H25: TRONTON | I25: 1 | J25: 1
A26: 02.09.2025 | B26: 3331548667 | C26: ALIEF | E26: PT. APP PURINUSA EKAPERSADA | F26: JABODETABEK | G26: 11348 | H26: TRONTON | I26: 1 | J26: 1
A27: 02.09.2025 | B27: 3331548673 | C27: ALIEF | D27: 24140290 | E27: PT. KATI KARTIKA MURNI CIKARANG | F27: JABODETABEK | G27: 24763 | H27: TRONTON | I27: 1 | J27: 1
A28: 02.09.2025 | B28: 3331548675 | C28: ALIEF | D28: 24140291 | E28: PT. APP PURINUSA EKAPERSADA | F28: JABODETABEK | G28: 22060 | H28: TRONTON | I28: 1 | J28: 1
A29: 01.09.2025 | B29: 3331548333 | C29: ALIEF | D29: 24140295 | E29: PT. APP PURINUSA EKAPERSADA | F29: JABODETABEK | G29: 22060 | H29: TRONTON | I29: 1 | J29: 1
A30: 02.09.2025 | B30: 3331548732 | C30: BRJ | D30: 24140296 | E30: PT. APP PURINUSA EKAPERSADA DEMAK | F30: JAWA TENGAH | G30: 33872 | H30: TRAILER | I30: 1 | J30: 1
A31: 02.09.2025 | B31: 3331548736 | C31: BRJ | D31: 24140297 | E31: PT. APP PURINUSA EKAPERSADA DEMAK | F31: JAWA TENGAH | G31: 44529 | H31: TRAILER | I31: 1 | J31: 1
A32: 02.09.2025 | B32: 3331548741 | C32: BRJ | D32: 24140298 | E32: PT. APP PURINUSA EKAPERSADA DEMAK | F32: JAWA TENGAH | G32: 45726 | H32: TRAILER | I32: 1 | J32: 1
A33: 02.09.2025 | B33: 3331548746 | C33: BRJ | D33: 24140299 | E33: PT. APP PURINUSA EKAPERSADA SEMARANG | F33: JAWA TENGAH | G33: 37035 | H33: TRAILER | I33: 1 | J33: 1
A34: 02.09.2025 | B34: 3331548749 | C34: BRJ | D34: 24140300 | E34: PT. APP PURINUSA EKAPERSADA SEMARANG | F34: JAWA TENGAH | G34: 33812 | H34: TRAILER | I34: 1 | J34: 1
A35: 02.09.2025 | B35: 3331548756 | C35: SIBA | D35: 24140301 | E35: PT. APP PURINUSA EKAPERSADA SEMARANG | F35: JAWA TENGAH | G35: 34290 | H35: TRAILER | I35: 1 | J35: 1
A36: 02.09.2025 | B36: 3331548760 | C36: ALIEF | D36: 24140303 | E36: PT. KEMASAN INDAH SEJAHTERA | F36: JABODETABEK | G36: 13963 | H36: TRONTON | I36: 1 | J36: 1
A37: 02.09.2025 | B37: 3331548761 | E37: PT. KEMASAN INDAH SEJAHTERA | F37: JABODETABEK | G37: 10480 | H37: TRONTON | I37: 1 | J37: 1
A38: 02.09.2025 | B38: 3331548736 | C38: BRJ | D38: 24140297 | E38: PT. APP PURINUSA EKAPERSADA DEMAK | F38: JAWA TENGAH | G38: 44529 | H38: TRAILER | I38: 1 | J38: 1 | K38: 0.17986111 | L38: 0.44444444
A39: 02.09.2025 | B39: 3331548749 | C39: ETI | D39: 24140300 | E39: PT. APP PURINUSA EKAPERSADA BAWEN | F39: JAWA TENGAH | G39: 35775.372 | H39: TRAILER | I39: 1 | J39: 1 | K39: =IFERROR(VLOOKUP(B39,'IN OUT'!F:G,2,FALSE), "BELUM MASUK") -> BELUM MASUK | L39: 0.090277778
A40: 02.09.2025 | B40: 3331548756 | C40: SIBA SURYA | D40: 24140301 | E40: PT. APP PURINUSA EKAPERSADA | F40: JAWA TENGAH | G40: 34495.741 | H40: TRAILER | I40: 1 | J40: 1 | K40: =IFERROR(VLOOKUP(B40,'IN OUT'!F:G,2,FALSE), "BELUM MASUK") -> BELUM MASUK | L40: -
A41: 03.09.2025 | B41: 3331548394 | C41: ALIEF | D41: 24140305 | E41: PT. HEXA PRIMA PERSADA TGR | F41: JABODETABEK | G41: 26626.47 | H41: TRONTON | I41: 1 | J41: 1 | K41: =IFERROR(VLOOKUP(B41,'IN OUT'!F:G,2,FALSE), "BELUM MASUK") -> BELUM MASUK | L41: 0.84027778
...

Sheet 20.10.25
A1: Plan tgl 20 OKT'25 jam 15.00 | F1: CARGO ADD | J1: CARGO NEXT DAY | N1: Summary (Plan+ Add + Next Day) | R1: Tanggal | S1: Delivery | T1: Vendor | U1: SN | V1: Name ship-to party | W1: AREA | X1: TOTAL WEIGHT | Y1: TRUCK TYPE | Z1: KEBUTUHAN | AA1: KETERSEDIAAN | AB1: GATE IN | AC1: Add | AD1: REMARK
A2: Realz update 21 OKT’25 jam 07.00 | F2: Tgl 20 OKT’25 diatas jam 15.00 | J2: Tgl 20 OKT’25 | R2: 17.10.2025 | S2: 3331562175 | T2: SILOG | U2: 24141788 | V2: PT PABRIK KERTAS TJIWI KIMIA SIDOARJO | W2: JAWA TIMUR | X2: 20751.508 | Y2: TRONTON | Z2: 1 | AA2: 1 | AB2: MASUK
A3: PRODUK | B3: JML TRUCK | F3: JMLTRUCK | J3: JMLTRUCK | N3: JML TRUCK | R3: 20.10.2025 | S3: 3331563029 | T3: = | U3: = | V3: = | W3: = | X3: = | Y3: = | Z3: = | AA3: = | AB3: =
B4: PLAN | C4: REALZ | D4: GAP | F4: ADD | G4: REALZ | H4: GAP | J4: NEXT DAY | K4: REALZ | L4: GAP | N4: PLAN + ADD + NEXT DAY | O4: REALZ | P4: GAP | R4: 20.10.2025 | S4: 3331562080 | T4: DAYA EKA | U4: 24141665 | V4: KREASI KOTAKMEGAH, PT (GD) DELI SERDANG | W4: LUAR PULAU | X4: =5848+18470 -> 24318 | Y4: 40 HC | Z4: 1 | AA4: 1 | AB4: MASUK
A5: BROWN | B5: {=SUMPRODUCT(--ISNUMBER(MATCH(TRIM(W1:W283), {"JABODETABEK","JAWA TENGAH","JAWA TIMUR","LUAR PULAU"}, 0)), --(AC1:AC283=""))} -> 22 | C5: {=SUMPRODUCT(--(LOWER(TRIM(AB1:AB309))="masuk"), --(ISNUMBER(MATCH(TRIM(W1:W309), {"JABODETABEK","JAWA TENGAH","JAWA TIMUR","LUAR PULAU"}, 0))), --(LOWER(AC1:AC309)<>"add"))} -> 20 | D5: =C5+-B5 -> -2 | F5: {=SUMPRODUCT(--(LOWER(AC1:AC309)="add"), --(ISNUMBER(MATCH(W1:W309, {"JABODETABEK","JAWA TENGAH","JAWA TIMUR","LUAR PULAU"}, 0))))} -> 5 | G5: {=SUMPRODUCT(--(LOWER(AB1:AB309)="masuk"), --(LOWER(AC1:AC309)="add"))} -> 5 | H5: =G5+-F5 -> 0 | J5: {=SUMPRODUCT(--(ISNUMBER(SEARCH("next day",LOWER(W1:W309)))+ISNUMBER(SEARCH("nextday",LOWER(W1:W309)))> 0))} -> 1 | K5: {=SUMPRODUCT(--(LOWER(AB1:AB309)="masuk"), --ISNUMBER(SEARCH("next day", LOWER(W1:W309))))} -> 1 | L5: =K5+-J5 -> 0 | N5: =B5+F5+J5 -> 28 | O5: =C5+G5+K5 -> 26 | P5: =D5+H5+L5 -> -2 | R5: 20.10.2025 | S5: 3331562082 | T5: = | U5: = | V5: = | W5: = | X5: = | Y5: = | Z5: = | AA5: = | AB5: =
B6: =SUM(B5) -> 22 | C6: =SUM(C5) -> 20 | D6: =SUM(D5) -> -2 | F6: =SUM(F5) -> 5 | G6: =SUM(G5) -> 5 | H6: =SUM(H5) -> 0 | J6: =SUM(J5) -> 1 | K6: =SUM(K5) -> 1 | L6: =SUM(L5) -> 0 | N6: =SUM(N5:N5) -> 28 | O6: =SUM(O5:O5) -> 26 | P6: =SUM(P5:P5) -> -2 | R6: 20.10.2025 | S6: 3331562084 | T6: DAYA EKA | U6: 24141666 | V6: KREASI KOTAKMEGAH, PT (GD) DELI SERDANG | W6: LUAR PULAU | X6: 22862.928 | Y6: 40 HC | Z6: 1 | AA6: 1 | AB6: MASUK
R7: 20.10.2025 | S7: 3331562086 | T7: DAYA EKA | U7: 24141670 | V7: KREASI KOTAKMEGAH, PT (GD) DELI SERDANG | W7: LUAR PULAU | X7: =12860+10175 -> 23035 | Y7: 40 HC | Z7: 1 | AA7: 1 | AB7: MASUK
A8: =A1 -> Plan tgl 20 OKT'25 jam 15.00 | F8: =F1 -> CARGO ADD | J8: =J1 -> CARGO NEXT DAY | N8: =N1 -> Summary (Plan+ Add + Next Day) | R8: 20.10.2025 | S8: 3331562087 | T8: = | U8: = | V8: = | W8: = | X8: = | Y8: = | Z8: = | AA8: = | AB8: =
A9: =A2 -> Realz update 21 OKT’25 jam 07.00 | F9: =F2 -> Tgl 20 OKT’25 diatas jam 15.00 | J9: =J2 -> Tgl 20 OKT’25 | R9: 20.10.2025 | S9: 3331562090 | T9: DAYA EKA | U9: 24141671 | V9: KREASI KOTAKMEGAH, PT (GD) DELI SERDANG | W9: LUAR PULAU | X9: 23429.74 | Y9: 40 HC | Z9: 1 | AA9: 1 | AB9: MASUK
A10: AREA | B10: JML TRUCK | F10: JMLTRUCK | J10: JMLTRUCK | N10: JML TRUCK | R10: 20.10.2025 | S10: 3331562094 | T10: DAYA EKA | U10: 24141679 | V10: KREASI KOTAKMEGAH, PT (GD) DELI SERDANG | W10: LUAR PULAU | X10: 23942.8 | Y10: 40 HC | Z10: 1 | AA10: 1 | AB10: MASUK
B11: PLAN | C11: REALZ | D11: GAP | F11: ADD | G11: REALZ | H11: GAP | J11: NEXT DAY | K11: REALZ | L11: GAP | N11: PLAN + ADD + NEXT DAY | O11: REALZ | P11: GAP | R11: 16.10.2025 | S11: 3331562099 | T11: DAYA EKA | U11: 24141677 | V11: PT. KREASI KOTAKMEGAH MEDAN | W11: LUAR PULAU | X11: 25373.835 | Y11: 40 HC | Z11: 1 | AA11: 1 | AB11: BELUM MASUK
A12: JABODETABEK | B12: {=SUMPRODUCT(--(TRIM(LOWER(W1:W309))="jabodetabek"), --(LOWER(AC1:AC309)<>"add"))} -> 6 | C12: {=SUMPRODUCT(--(LOWER(AB1:AB309)="masuk"), --(TRIM(LOWER(W1:W309))="jabodetabek"), --(LOWER(AC1:AC309)<>"add"))} -> 6 | D12: =C12+-B12 -> 0 | F12: {=SUMPRODUCT(--(LOWER(AC1:AC309)="add"), --(TRIM(LOWER(W1:W309))="jabodetabek"))} -> 1 | G12: {=SUMPRODUCT(--(LOWER(AB1:AB309)="masuk"), --(LOWER(AC1:AC309)="add"), --(TRIM(LOWER(W1:W309))="jabodetabek"))} -> 1 | H12: =G12+-F12 -> 0 | J12: {=SUMPRODUCT(--(ISNUMBER(SEARCH("jabodetabek next day",LOWER(W1:W309)))+ISNUMBER(SEARCH("jabodetabek nextday",LOWER(W1:W309)))> 0))} -> 0 | K12: {=SUMPRODUCT(--(LOWER(AB1:AB309)="masuk"), --(LOWER(TRIM(W1:W309))="jabodetabek next day"))} -> 0 | L12: =K12+-J12 -> 0 | N12: =B12+F12+J12 -> 7 | O12: =C12+G12+K12 -> 7 | P12: =D12+H12+L12 -> 0 | R12: 16.10.2025 | S12: 3331562100 | T12: DAYA EKA | U12: 24141678 | V12: PT. KREASI KOTAKMEGAH MEDAN | W12: LUAR PULAU | X12: 23997.627 | Y12: 40 HC | Z12: 1 | AA12: 1 | AB12: BELUM MASUK
